> spring对RuntimeException会自动回滚吗？



```java
	@Override
//	@Transactional(rollbackFor=Exception.class)
	public void testService() {
		MgmAwardReceiveRecord entity = new MgmAwardReceiveRecord();
		entity.setActivityId(1L);
		entity.setAwardId(1L);
		entity.setNewCustomerId("123456789");
		//...
		receiveService.addAwardReceiveRecord(entity);
		
		throw new RuntimeException();
		
	}
```

- 此处的entity插入成功，即使之后出现运行时异常也不会自动回滚

```java
	@Override
	@Transactional(rollbackFor=Exception.class)
	public void testService() {
		MgmAwardReceiveRecord entity = new MgmAwardReceiveRecord();
		entity.setActivityId(1L);
		entity.setAwardId(1L);
		entity.setNewCustomerId("123456789");
		//...
		receiveService.addAwardReceiveRecord(entity);
		
		throw new RuntimeException();
		
	}
```

- 此处的entity没有插入成功，加了事务注解后可以对RuntimeException异常处理事务回滚



> 已经被catch到了的exception还会触发回滚吗？

```java
	@Override
	@Transactional(rollbackFor=Exception.class)
	public void testService() {
		MgmAwardReceiveRecord entity = new MgmAwardReceiveRecord();
		entity.setActivityId(1L);
		entity.setAwardId(1L);
		entity.setNewCustomerId("123456789");
		
		receiveService.addAwardReceiveRecord(entity);
		
		try {
			throw new CommonServiceException();
		} catch (CommonServiceException e) {
			// TODO Auto-generated catch block
			e.printStackTrace();
		}
		
	}
```

- 此处的entity插入成功，已经被catch到了的exception不会触发回滚



